<?xml version="1.0"?>
<robot xmlns:xacro="http://www.ros.org/wiki/xacro" name="bldc_motor">
    <xacro:include filename="inertial_macros.xacro"/>
    <!-- Bldc Motors Base -->
    <link name="base_link_motor_b_L">
        <visual>
            <geometry>
                <cylinder radius="0.02" length="0.01"/>
            </geometry>
            <origin xyz="0.0 0.0 0.0" rpy="0.0 0.0 0.0"/>
            <material name="gray"/>    
        </visual>

        <collision>
            <geometry>
                <cylinder radius="0.02" length="0.01"/>
            </geometry>
        </collision>

        <xacro:inertial_cylinder mass= "0.06" radius="0.02" length="0.01">
            <origin xyz="0 0 0" rpy="0 0 0"/>
        </xacro:inertial_cylinder>
    </link>

    <joint name="base_joint_b_L" type="fixed">
        <parent link="beam_link"/>
        <child link="base_link_motor_b_L"/>
        <origin xyz="0.0 0.25 0.01" rpy="0.0 0.0 0.0"/>
    </joint>

    <link name="base_link_motor_b_R">
        <visual>
            <geometry>
                <cylinder radius="0.02" length="0.01"/>
            </geometry>
            <origin xyz="0.0 0.0 0.0" rpy="0.0 ${pi} 0.0"/>
            <material name="gray"/>    
        </visual>

        <collision>
            <geometry>
                <cylinder radius="0.02" length="0.01"/>
            </geometry>
        </collision>

        <xacro:inertial_cylinder mass= "0.06" radius="0.02" length="0.01">
            <origin xyz="0 0 0" rpy="0 0 0"/>
        </xacro:inertial_cylinder>
    </link>

    <joint name="base_joint_b_R" type="fixed">
        <parent link="beam_link"/>
        <child link="base_link_motor_b_R"/>
        <origin xyz="0.0 0.20 -0.01" rpy="0.0 0.0 0.0"/>
    </joint>


    <link name="base_link_motor_pitch">
        <visual>
            <geometry>
                <cylinder radius="0.02" length="0.01"/>
            </geometry>
            <origin xyz="0.0 0.0 0.0" rpy="0.0 0.0 0.0"/>
            <material name="gray"/>    
        </visual>

        <collision>
            <geometry>
                <cylinder radius="0.02" length="0.01"/>
            </geometry>
        </collision>
        <xacro:inertial_cylinder mass= "0.06" radius="0.02" length="0.01">
            <origin xyz="0 0 0" rpy="0 0 0"/>
        </xacro:inertial_cylinder>
    </link>


    <joint name="base_joint__motor_pitch" type="fixed">
        <parent link="beam_link"/>
        <child link="base_link_motor_pitch"/>
        <origin xyz="0.01 -0.25 0.0" rpy="0.0 ${pi/2} 0.0"/>
    </joint>

    <!-- Rotors for BLDC  -->
    
    <link name="rotor_L">
        <visual>
            <geometry>
                <cylinder radius="0.12" length="0.001"/>
            </geometry>
            <origin xyz="0.0 0.0 0.0" rpy="0.0 0.0 0.0"/>
            <material name="blue"/>
        </visual>

        <collision>
            <geometry>
                <cylinder radius="0.12" length="0.001"/>
            </geometry>
        </collision>

        <xacro:inertial_cylinder mass= "0.02" radius="0.12" length="0.001">
            <origin xyz="0 0 0" rpy="0 0 0"/>
        </xacro:inertial_cylinder>
    </link>

    <joint name="rotor_l_joint" type="continuous">
        <parent link="base_link_motor_b_L"/>
        <child link="rotor_L"/>
        <origin xyz="0.0 0.0 0.005" rpy="0.0 0.0 0.0"/>
        <axis xyz="0.0 0.0 1.0"/>
    </joint>

    <link name="rotor_R">
        <visual>
            <geometry>
                <cylinder radius="0.12" length="0.001"/>
            </geometry>
            <origin xyz="0.0 0.0 0.0" rpy="0.0 0.0 0.0"/>
            <material name="blue"/>
        </visual>

        <collision>
            <geometry>
                <cylinder radius="0.12" length="0.001"/>
            </geometry>
        </collision>
        <xacro:inertial_cylinder mass= "0.02" radius="0.12" length="0.001">
            <origin xyz="0 0 0" rpy="0 0 0"/>
        </xacro:inertial_cylinder>
    </link>

    <joint name="rotor_r_joint" type="continuous">
        <parent link="base_link_motor_b_R"/>
        <child link="rotor_R"/>
        <origin xyz="0.0 0.0 -0.005" rpy="0.0 0.0 0.0"/>
        <axis xyz="0.0 0.0 1.0"/>
    </joint>

    <link name="rotor_pitch">
        <visual>
            <geometry>
                <cylinder radius="0.12" length="0.001"/>
            </geometry>
            <origin xyz="0.0 0.0 0.0" rpy="0.0 0.0 0.0"/>
            <material name="blue"/>
        </visual>

        <collision>
            <geometry>
                <cylinder radius="0.12" length="0.001"/>
            </geometry>
        </collision>

        <xacro:inertial_cylinder mass= "0.02" radius="0.12" length="0.001">
            <origin xyz="0 0 0" rpy="0 0 0"/>
        </xacro:inertial_cylinder>
    </link>

    <joint name="rotor_pitch_joint" type="continuous">
        <parent link="base_link_motor_pitch"/>
        <child link="rotor_pitch"/>
        <origin xyz="0.0 0.0 0.005" rpy="0.0 0.0 0.0"/>
        <axis xyz="0.0 0.0 1.0"/>
    </joint>
</robot>